<?xml version="1.0" encoding="utf-8"?>
<robot
  name="mod_test">
  <link
    name="base_link">
    <inertial>
      <origin
        xyz="-1.5226495220944E-06 1.5812928362389E-07 -5.05247252856584E-07"
        rpy="0 0 0" />
      <mass
        value="0.422806992949252" />
      <inertia
        ixx="0.00237499139253511"
        ixy="1.5717831530364E-08"
        ixz="1.49286265366169E-08"
        iyy="0.00237502154661776"
        iyz="-2.02154172619351E-08"
        izz="0.00237502595466009" />
    </inertial>
    <visual>
      <origin
        xyz="0 0 0"
        rpy="0 0 0" />
      <geometry>
        <mesh
          filename="package://meshes/base_link.STL" />
      </geometry>
      <material
        name="">
        <color
          rgba="0.498039215686275 0.498039215686275 0.498039215686275 1" />
      </material>
    </visual>
    <collision>
      <origin
        xyz="0 0 0"
        rpy="0 0 0" />
      <geometry>
        <mesh
          filename="package://meshes/base_link.STL" />
      </geometry>
    </collision>
  </link>
  <link
   name="100">
   <inertial>
      <origin
        xyz="0 0 0.028508"
        rpy="0 0 0" />
      <mass
        value="0.076173" />
      <inertia
        ixx="3.054E-05"
        ixy="0.000000"
        ixz="-0.000000"
        iyy="2.1077E-05"
        iyz="-0.000000"
        izz="2.1165E-05" />
    </inertial>
    <visual>
      <origin
        xyz="0 0 0"
        rpy="0 0 0" />
      <geometry>
        <mesh
          filename="package://meshes/1.STL" />
      </geometry>
      <material
        name="">
        <color
          rgba="1 1 1 1" />
      </material>
    </visual>
    <collision>
      <origin
        xyz="0 0 0"
        rpy="0 0 0" />
      <geometry>
        <mesh
          filename="package://meshes/1.STL" />
      </geometry>
    </collision>
  </link>
  <joint
    name="body_100"
    type="fixed">
    <origin
        xyz="0.051620 -0.071049 -0.016769"
        rpy="1.935587 -1.017234 0.314221" />
    <parent
      link="base_link" />
    <child
      link="100" />
    <axis
      xyz="0 0 0" />
  </joint>
  <link
    name="101">
    <inertial>
      <origin
        xyz="0.060018 -1.4108E-06 1.4108E-06"
        rpy="0 0 0" />
    <mass
        value="0.10689" />
      <inertia
        ixx="3.2684e-05"
        ixy="-2.5662e-09"
        ixz="2.5662e-09"
        iyy="8.4132e-05"
        iyz="-2.1275e-13"
        izz="8.4583e-05" />
    </inertial>
    <visual>
      <origin
        xyz="0 0 0"
        rpy="0 0 0" />
      <geometry>
        <mesh
          filename="package://meshes/module9.STL" />
      </geometry>
      <material
        name="">
        <color
          rgba="0.79216 0.81961 0.93333 1" />
      </material>
    </visual>
    <collision>
      <origin
        xyz="0 0 0"
        rpy="0 0 0" />
      <geometry>
        <mesh
          filename="package://meshes/module9.STL" />
      </geometry>
    </collision>
  </link>
  <joint
    name="100_101"
    type="revolute">
    <origin
      xyz="0 0 0.04"
      rpy="-1.558 -1.5708 -0.012835" />
    <parent
      link="100" />
    <child
      link="101" />
    <axis
      xyz="0 0 1" />
    <limit
      lower="-6.28"
      upper="6.28"
      effort="10"
      velocity="100" />
  </joint>
  <link
    name="102">
    <inertial>
      <origin
        xyz="0.060018 -1.4108E-06 1.4108E-06"
        rpy="0 0 0" />
    <mass
        value="0.10689" />
      <inertia
        ixx="3.2684e-05"
        ixy="-2.5662e-09"
        ixz="2.5662e-09"
        iyy="8.4132e-05"
        iyz="-2.1275e-13"
        izz="8.4583e-05" />
    </inertial>
    <visual>
      <origin
        xyz="0 0 0"
        rpy="0 0 0" />
      <geometry>
        <mesh
          filename="package://meshes/module3.STL" />
      </geometry>
      <material
        name="">
        <color
          rgba="0.79216 0.81961 0.93333 1" />
      </material>
    </visual>
    <collision>
      <origin
        xyz="0 0 0"
        rpy="0 0 0" />
      <geometry>
        <mesh
          filename="package://meshes/module3.STL" />
      </geometry>
    </collision>
  </link>
  <joint
    name="101_102"
    type="revolute">
    <origin
      xyz="0.0816 0 0"
      rpy="4.712389 0 0" />
    <parent
      link="101" />
    <child
      link="102" />
    <axis
      xyz="0 0 1" />
    <limit
      lower="-6.28"
      upper="6.28"
      effort="10"
      velocity="100" />
  </joint>
  <link
    name="103">
    <inertial>
      <origin
        xyz="0.051733 -0.042281 -1.3878E-17"
        rpy="0 0 0" />
    <mass
        value="0.12059" />
      <inertia
        ixx="0.00025425"
        ixy="4.8319E-05"
        ixz="0"
        iyy="5.0194E-05"
        iyz="-3.3141E-21"
        izz="0.00027482" />
    </inertial>
    <visual>
      <origin
        xyz="0 0 0"
        rpy="0 0 0" />
      <geometry>
        <mesh
          filename="package://meshes/leg.STL" />
      </geometry>
      <material
        name="">
        <color
          rgba="0.79216 0.81961 0.93333 1" />
      </material>
    </visual>
    <collision>
      <origin
        xyz="0 0 0"
        rpy="0 0 0" />
      <geometry>
        <mesh
          filename="package://meshes/leg.STL" />
      </geometry>
    </collision>
  </link>
  <joint
    name="102_103"
    type="revolute">
    <origin
      xyz="0.0816 0 0"
      rpy="1.570796 0 0" />
    <parent
      link="102" />
    <child
      link="103" />
    <axis
      xyz="0 0 1" />
    <limit
      lower="-6.28"
      upper="6.28"
      effort="10"
      velocity="100" />
  </joint>
  <link
   name="70">
   <inertial>
      <origin
        xyz="0 0 0.028508"
        rpy="0 0 0" />
      <mass
        value="0.076173" />
      <inertia
        ixx="3.054E-05"
        ixy="0.000000"
        ixz="-0.000000"
        iyy="2.1077E-05"
        iyz="-0.000000"
        izz="2.1165E-05" />
    </inertial>
    <visual>
      <origin
        xyz="0 0 0"
        rpy="0 0 0" />
      <geometry>
        <mesh
          filename="package://meshes/1.STL" />
      </geometry>
      <material
        name="">
        <color
          rgba="1 1 1 1" />
      </material>
    </visual>
    <collision>
      <origin
        xyz="0 0 0"
        rpy="0 0 0" />
      <geometry>
        <mesh
          filename="package://meshes/1.STL" />
      </geometry>
    </collision>
  </link>
  <joint
    name="body_70"
    type="fixed">
    <origin
        xyz="0.051620 0.071049 0.016769"
        rpy="1.206006 -1.017234 2.827371" />
    <parent
      link="base_link" />
    <child
      link="70" />
    <axis
      xyz="0 0 0" />
  </joint>
  <link
    name="71">
    <inertial>
      <origin
        xyz="0.060018 -1.4108E-06 1.4108E-06"
        rpy="0 0 0" />
    <mass
        value="0.10689" />
      <inertia
        ixx="3.2684e-05"
        ixy="-2.5662e-09"
        ixz="2.5662e-09"
        iyy="8.6498e-05"
        iyz="-4.0975e-06"
        izz="8.2217e-05" />
    </inertial>
    <visual>
      <origin
        xyz="0 0 0"
        rpy="0 0 0" />
      <geometry>
        <mesh
          filename="package://meshes/module10.STL" />
      </geometry>
      <material
        name="">
        <color
          rgba="0.79216 0.81961 0.93333 1" />
      </material>
    </visual>
    <collision>
      <origin
        xyz="0 0 0"
        rpy="0 0 0" />
      <geometry>
        <mesh
          filename="package://meshes/module10.STL" />
      </geometry>
    </collision>
  </link>
  <joint
    name="70_71"
    type="revolute">
    <origin
      xyz="0 0 0.04"
      rpy="-1.558 -1.5708 -0.012835" />
    <parent
      link="70" />
    <child
      link="71" />
    <axis
      xyz="0 0 1" />
    <limit
      lower="-6.28"
      upper="6.28"
      effort="10"
      velocity="100" />
  </joint>
  <link
    name="72">
    <inertial>
      <origin
        xyz="0.060018 -1.4108E-06 1.4108E-06"
        rpy="0 0 0" />
    <mass
        value="0.10689" />
      <inertia
        ixx="3.2684e-05"
        ixy="-2.5662e-09"
        ixz="2.5662e-09"
        iyy="9.3595e-05"
        iyz="-2.1275e-13"
        izz="7.512e-05" />
    </inertial>
    <visual>
      <origin
        xyz="0 0 0"
        rpy="0 0 0" />
      <geometry>
        <mesh
          filename="package://meshes/module6.STL" />
      </geometry>
      <material
        name="">
        <color
          rgba="0.79216 0.81961 0.93333 1" />
      </material>
    </visual>
    <collision>
      <origin
        xyz="0 0 0"
        rpy="0 0 0" />
      <geometry>
        <mesh
          filename="package://meshes/module6.STL" />
      </geometry>
    </collision>
  </link>
  <joint
    name="71_72"
    type="revolute">
    <origin
      xyz="0.0816 0 0"
      rpy="5.235988 0 0" />
    <parent
      link="71" />
    <child
      link="72" />
    <axis
      xyz="0 0 1" />
    <limit
      lower="-6.28"
      upper="6.28"
      effort="10"
      velocity="100" />
  </joint>
  <link
    name="73">
    <inertial>
      <origin
        xyz="0.051733 -0.042281 -1.3878E-17"
        rpy="0 0 0" />
    <mass
        value="0.12059" />
      <inertia
        ixx="0.00025425"
        ixy="4.8319E-05"
        ixz="0"
        iyy="5.0194E-05"
        iyz="-3.3141E-21"
        izz="0.00027482" />
    </inertial>
    <visual>
      <origin
        xyz="0 0 0"
        rpy="0 0 0" />
      <geometry>
        <mesh
          filename="package://meshes/leg.STL" />
      </geometry>
      <material
        name="">
        <color
          rgba="0.79216 0.81961 0.93333 1" />
      </material>
    </visual>
    <collision>
      <origin
        xyz="0 0 0"
        rpy="0 0 0" />
      <geometry>
        <mesh
          filename="package://meshes/leg.STL" />
      </geometry>
    </collision>
  </link>
  <joint
    name="72_73"
    type="revolute">
    <origin
      xyz="0.0816 0 0"
      rpy="3.141593 0 0" />
    <parent
      link="72" />
    <child
      link="73" />
    <axis
      xyz="0 0 1" />
    <limit
      lower="-6.28"
      upper="6.28"
      effort="10"
      velocity="100" />
  </joint>
  <link
   name="80">
   <inertial>
      <origin
        xyz="0 0 0.028508"
        rpy="0 0 0" />
      <mass
        value="0.076173" />
      <inertia
        ixx="3.054E-05"
        ixy="0.000000"
        ixz="0.000000"
        iyy="2.1077E-05"
        iyz="0.000021"
        izz="2.1165E-05" />
    </inertial>
    <visual>
      <origin
        xyz="0 0 0"
        rpy="0 0 0" />
      <geometry>
        <mesh
          filename="package://meshes/1.STL" />
      </geometry>
      <material
        name="">
        <color
          rgba="1 1 1 1" />
      </material>
    </visual>
    <collision>
      <origin
        xyz="0 0 0"
        rpy="0 0 0" />
      <geometry>
        <mesh
          filename="package://meshes/1.STL" />
      </geometry>
    </collision>
  </link>
  <joint
    name="body_80"
    type="fixed">
    <origin
        xyz="-0.051620 0.071049 0.016769"
        rpy="-1.206006 -1.017234 0.314221" />
    <parent
      link="base_link" />
    <child
      link="80" />
    <axis
      xyz="0 0 0" />
  </joint>
  <link
    name="81">
    <inertial>
      <origin
        xyz="0.060018 -1.4108E-06 1.4108E-06"
        rpy="0 0 0" />
    <mass
        value="0.10689" />
      <inertia
        ixx="3.2684e-05"
        ixy="-2.5662e-09"
        ixz="2.5662e-09"
        iyy="8.6498e-05"
        iyz="4.0975e-06"
        izz="8.2217e-05" />
    </inertial>
    <visual>
      <origin
        xyz="0 0 0"
        rpy="0 0 0" />
      <geometry>
        <mesh
          filename="package://meshes/module2.STL" />
      </geometry>
      <material
        name="">
        <color
          rgba="0.79216 0.81961 0.93333 1" />
      </material>
    </visual>
    <collision>
      <origin
        xyz="0 0 0"
        rpy="0 0 0" />
      <geometry>
        <mesh
          filename="package://meshes/module2.STL" />
      </geometry>
    </collision>
  </link>
  <joint
    name="80_81"
    type="revolute">
    <origin
      xyz="0 0 0.04"
      rpy="-1.558 -1.5708 -0.012835" />
    <parent
      link="80" />
    <child
      link="81" />
    <axis
      xyz="0 0 1" />
    <limit
      lower="-6.28"
      upper="6.28"
      effort="10"
      velocity="100" />
  </joint>
  <link
    name="82">
    <inertial>
      <origin
        xyz="0.060018 -1.4108E-06 1.4108E-06"
        rpy="0 0 0" />
    <mass
        value="0.10689" />
      <inertia
        ixx="3.2684e-05"
        ixy="-2.5662e-09"
        ixz="2.5662e-09"
        iyy="9.3595e-05"
        iyz="-2.1275e-13"
        izz="7.512e-05" />
    </inertial>
    <visual>
      <origin
        xyz="0 0 0"
        rpy="0 0 0" />
      <geometry>
        <mesh
          filename="package://meshes/module6.STL" />
      </geometry>
      <material
        name="">
        <color
          rgba="0.79216 0.81961 0.93333 1" />
      </material>
    </visual>
    <collision>
      <origin
        xyz="0 0 0"
        rpy="0 0 0" />
      <geometry>
        <mesh
          filename="package://meshes/module6.STL" />
      </geometry>
    </collision>
  </link>
  <joint
    name="81_82"
    type="revolute">
    <origin
      xyz="0.0816 0 0"
      rpy="1.047198 0 0" />
    <parent
      link="81" />
    <child
      link="82" />
    <axis
      xyz="0 0 1" />
    <limit
      lower="-6.28"
      upper="6.28"
      effort="10"
      velocity="100" />
  </joint>
  <link
    name="83">
    <inertial>
      <origin
        xyz="0.051733 -0.042281 -1.3878E-17"
        rpy="0 0 0" />
    <mass
        value="0.12059" />
      <inertia
        ixx="0.00025425"
        ixy="4.8319E-05"
        ixz="0"
        iyy="5.0194E-05"
        iyz="-3.3141E-21"
        izz="0.00027482" />
    </inertial>
    <visual>
      <origin
        xyz="0 0 0"
        rpy="0 0 0" />
      <geometry>
        <mesh
          filename="package://meshes/leg.STL" />
      </geometry>
      <material
        name="">
        <color
          rgba="0.79216 0.81961 0.93333 1" />
      </material>
    </visual>
    <collision>
      <origin
        xyz="0 0 0"
        rpy="0 0 0" />
      <geometry>
        <mesh
          filename="package://meshes/leg.STL" />
      </geometry>
    </collision>
  </link>
  <joint
    name="82_83"
    type="revolute">
    <origin
      xyz="0.0816 0 0"
      rpy="3.141593 0 0" />
    <parent
      link="82" />
    <child
      link="83" />
    <axis
      xyz="0 0 1" />
    <limit
      lower="-6.28"
      upper="6.28"
      effort="10"
      velocity="100" />
  </joint>
  <link
   name="140">
   <inertial>
      <origin
        xyz="0 0 0.028508"
        rpy="0 0 0" />
      <mass
        value="0.076173" />
      <inertia
        ixx="3.054E-05"
        ixy="0.000000"
        ixz="0.000000"
        iyy="2.1077E-05"
        iyz="0.000021"
        izz="2.1165E-05" />
    </inertial>
    <visual>
      <origin
        xyz="0 0 0"
        rpy="0 0 0" />
      <geometry>
        <mesh
          filename="package://meshes/1.STL" />
      </geometry>
      <material
        name="">
        <color
          rgba="1 1 1 1" />
      </material>
    </visual>
    <collision>
      <origin
        xyz="0 0 0"
        rpy="0 0 0" />
      <geometry>
        <mesh
          filename="package://meshes/1.STL" />
      </geometry>
    </collision>
  </link>
  <joint
    name="body_140"
    type="fixed">
    <origin
        xyz="-0.051620 -0.071049 -0.016769"
        rpy="-1.935587 -1.017234 2.827371" />
    <parent
      link="base_link" />
    <child
      link="140" />
    <axis
      xyz="0 0 0" />
  </joint>
  <link
    name="141">
    <inertial>
      <origin
        xyz="0.060018 -1.4108E-06 1.4108E-06"
        rpy="0 0 0" />
    <mass
        value="0.10689" />
      <inertia
        ixx="3.2684e-05"
        ixy="-2.5662e-09"
        ixz="2.5662e-09"
        iyy="8.4132e-05"
        iyz="-2.1275e-13"
        izz="8.4583e-05" />
    </inertial>
    <visual>
      <origin
        xyz="0 0 0"
        rpy="0 0 0" />
      <geometry>
        <mesh
          filename="package://meshes/module3.STL" />
      </geometry>
      <material
        name="">
        <color
          rgba="0.79216 0.81961 0.93333 1" />
      </material>
    </visual>
    <collision>
      <origin
        xyz="0 0 0"
        rpy="0 0 0" />
      <geometry>
        <mesh
          filename="package://meshes/module3.STL" />
      </geometry>
    </collision>
  </link>
  <joint
    name="140_141"
    type="revolute">
    <origin
      xyz="0 0 0.04"
      rpy="-1.558 -1.5708 -0.012835" />
    <parent
      link="140" />
    <child
      link="141" />
    <axis
      xyz="0 0 1" />
    <limit
      lower="-6.28"
      upper="6.28"
      effort="10"
      velocity="100" />
  </joint>
  <link
    name="142">
    <inertial>
      <origin
        xyz="0.060018 -1.4108E-06 1.4108E-06"
        rpy="0 0 0" />
    <mass
        value="0.10689" />
      <inertia
        ixx="3.2684e-05"
        ixy="-2.5662e-09"
        ixz="2.5662e-09"
        iyy="8.4132e-05"
        iyz="-2.1275e-13"
        izz="8.4583e-05" />
    </inertial>
    <visual>
      <origin
        xyz="0 0 0"
        rpy="0 0 0" />
      <geometry>
        <mesh
          filename="package://meshes/module9.STL" />
      </geometry>
      <material
        name="">
        <color
          rgba="0.79216 0.81961 0.93333 1" />
      </material>
    </visual>
    <collision>
      <origin
        xyz="0 0 0"
        rpy="0 0 0" />
      <geometry>
        <mesh
          filename="package://meshes/module9.STL" />
      </geometry>
    </collision>
  </link>
  <joint
    name="141_142"
    type="revolute">
    <origin
      xyz="0.0816 0 0"
      rpy="1.570796 0 0" />
    <parent
      link="141" />
    <child
      link="142" />
    <axis
      xyz="0 0 1" />
    <limit
      lower="-6.28"
      upper="6.28"
      effort="10"
      velocity="100" />
  </joint>
  <link
    name="143">
    <inertial>
      <origin
        xyz="0.051733 -0.042281 -1.3878E-17"
        rpy="0 0 0" />
    <mass
        value="0.12059" />
      <inertia
        ixx="0.00025425"
        ixy="4.8319E-05"
        ixz="0"
        iyy="5.0194E-05"
        iyz="-3.3141E-21"
        izz="0.00027482" />
    </inertial>
    <visual>
      <origin
        xyz="0 0 0"
        rpy="0 0 0" />
      <geometry>
        <mesh
          filename="package://meshes/leg.STL" />
      </geometry>
      <material
        name="">
        <color
          rgba="0.79216 0.81961 0.93333 1" />
      </material>
    </visual>
    <collision>
      <origin
        xyz="0 0 0"
        rpy="0 0 0" />
      <geometry>
        <mesh
          filename="package://meshes/leg.STL" />
      </geometry>
    </collision>
  </link>
  <joint
    name="142_143"
    type="revolute">
    <origin
      xyz="0.0816 0 0"
      rpy="4.712389 0 0" />
    <parent
      link="142" />
    <child
      link="143" />
    <axis
      xyz="0 0 1" />
    <limit
      lower="-6.28"
      upper="6.28"
      effort="10"
      velocity="100" />
  </joint>
  <link
    name = "ball_1">
    <inertial>
    <origin
        xyz="0 0 0"
        rpy="0 0 0" />
    <mass
        value="0" />
      <inertia
        ixx="0"
        ixy="0"
        ixz="0"
        iyy="0"
        iyz="0"
        izz="0" />
    </inertial>    <visual>
      <origin
        xyz="0 0 0"
        rpy="0 0 0" />
     <geometry>
        <sphere radius = "0.01"/>
      </geometry>
      <material
        name="green">
        <color
          rgba="0.22 1 0.4 1" />
      </material>
    </visual>
  </link>
  <joint
  name="103_ball1"
  type="fixed">
    <origin
      xyz="0.0612 -0.13431 0"
      rpy="0 0 0" />
    <parent
      link="103" />
    <child
      link="ball_1" />
    <axis
      xyz="0 0 0" />
  </joint>
  <link
    name = "ball_2">
    <inertial>
    <origin
        xyz="0 0 0"
        rpy="0 0 0" />
    <mass
        value="0" />
      <inertia
        ixx="0"
        ixy="0"
        ixz="0"
        iyy="0"
        iyz="0"
        izz="0" />
    </inertial>    <visual>
      <origin
        xyz="0 0 0"
        rpy="0 0 0" />
      <geometry>
        <sphere radius = "0.01"/>
      </geometry>
      <material
        name="blue">
        <color
          rgba="0.16 0.52 0.8 1" />
      </material>
    </visual>
  </link>
  <joint
  name="73_ball2"
  type="fixed">
    <origin
      xyz="0.0612 -0.13431 0"
      rpy="0 0 0" />
    <parent
      link="73" />
    <child
      link="ball_2" />
    <axis
      xyz="0 0 0" />
  </joint>
  <link
    name = "ball_3">
    <inertial>
    <origin
        xyz="0 0 0"
        rpy="0 0 0" />
    <mass
        value="0" />
      <inertia
        ixx="0"
        ixy="0"
        ixz="0"
        iyy="0"
        iyz="0"
        izz="0" />
    </inertial>    <visual>
      <origin
        xyz="0 0 0"
        rpy="0 0 0" />
     <geometry>
        <sphere radius = "0.01"/>
      </geometry>
      <material
        name="blue">
        <color
          rgba="0.16 0.52 0.8 1" />
      </material>
    </visual>
  </link>
  <joint
  name="83_ball3"
  type="fixed">
    <origin
      xyz="0.0612 -0.13431 0"
      rpy="0 0 0" />
    <parent
      link="83" />
    <child
      link="ball_3" />
    <axis
      xyz="0 0 0" />
  </joint>
  <link
    name = "ball_4">
    <inertial>
    <origin
        xyz="0 0 0"
        rpy="0 0 0" />
    <mass
        value="0" />
      <inertia
        ixx="0"
        ixy="0"
        ixz="0"
        iyy="0"
        iyz="0"
        izz="0" />
    </inertial>    <visual>
      <origin
        xyz="0 0 0"
        rpy="0 0 0" />
      <geometry>
        <sphere radius = "0.01"/>
      </geometry>
      <material
        name="yellow">
        <color
          rgba="1 1 0 1" />
      </material>
    </visual>
  </link>
  <joint
  name="143_ball4"
  type="fixed">
    <origin
      xyz="0.0612 -0.13431 0"
      rpy="0 0 0" />
    <parent
      link="143" />
    <child
      link="ball_4" />
    <axis
      xyz="0 0 0" />
  </joint>
</robot>