<?xml version="1.0" encoding="utf-8"?>
<robot
  name="mod_test">
  <link
    name="base_link">
    <inertial>
      <origin
        xyz="-1.5226495220944E-06 1.5812928362389E-07 -5.05247252856584E-07"
        rpy="0 0 0" />
      <mass
        value="0.422806992949252" />
      <inertia
        ixx="0.00237499139253511"
        ixy="1.5717831530364E-08"
        ixz="1.49286265366169E-08"
        iyy="0.00237502154661776"
        iyz="-2.02154172619351E-08"
        izz="0.00237502595466009" />
    </inertial>
    <visual>
      <origin
        xyz="0 0 0"
        rpy="0 0 0" />
      <geometry>
        <mesh
          filename="package://meshes/base_link.STL" />
      </geometry>
      <material
        name="">
        <color
          rgba="0.498039215686275 0.498039215686275 0.498039215686275 1" />
      </material>
    </visual>
    <collision>
      <origin
        xyz="0 0 0"
        rpy="0 0 0" />
      <geometry>
        <mesh
          filename="package://meshes/base_link.STL" />
      </geometry>
    </collision>
  </link>
  <link
   name="150">
   <inertial>
      <origin
        xyz="0 0 0.028508"
        rpy="0 0 0" />
      <mass
        value="0.076173" />
      <inertia
        ixx="3.054E-05"
        ixy="-0.000000"
        ixz="-0.000000"
        iyy="2.1077E-05"
        iyz="-0.000000"
        izz="2.1165E-05" />
    </inertial>
    <visual>
      <origin
        xyz="0 0 0"
        rpy="0 0 0" />
      <geometry>
        <mesh
          filename="package://meshes/1.STL" />
      </geometry>
      <material
        name="">
        <color
          rgba="1 1 1 1" />
      </material>
    </visual>
    <collision>
      <origin
        xyz="0 0 0"
        rpy="0 0 0" />
      <geometry>
        <mesh
          filename="package://meshes/1.STL" />
      </geometry>
    </collision>
  </link>
  <joint
    name="body_150"
    type="fixed">
    <origin
        xyz="0.031905 -0.043913 -0.071046"
        rpy="2.489189 -0.000000 0.628319" />
    <parent
      link="base_link" />
    <child
      link="150" />
    <axis
      xyz="0 0 0" />
  </joint>
  <link
    name="151">
    <inertial>
      <origin
        xyz="0.060018 -1.4108E-06 1.4108E-06"
        rpy="0 0 0" />
    <mass
        value="0.10689" />
      <inertia
        ixx="3.2684e-05"
        ixy="-2.5662e-09"
        ixz="2.5662e-09"
        iyy="8.4132e-05"
        iyz="-2.1275e-13"
        izz="8.4583e-05" />
    </inertial>
    <visual>
      <origin
        xyz="0 0 0"
        rpy="0 0 0" />
      <geometry>
        <mesh
          filename="package://meshes/module9.STL" />
      </geometry>
      <material
        name="">
        <color
          rgba="0.79216 0.81961 0.93333 1" />
      </material>
    </visual>
    <collision>
      <origin
        xyz="0 0 0"
        rpy="0 0 0" />
      <geometry>
        <mesh
          filename="package://meshes/module9.STL" />
      </geometry>
    </collision>
  </link>
  <joint
    name="150_151"
    type="revolute">
    <origin
      xyz="0 0 0.04"
      rpy="-1.558 -1.5708 -0.012835" />
    <parent
      link="150" />
    <child
      link="151" />
    <axis
      xyz="0 0 1" />
    <limit
      lower="-6.28"
      upper="6.28"
      effort="10"
      velocity="100" />
  </joint>
  <link
    name="152">
    <inertial>
      <origin
        xyz="0.060018 -1.4108E-06 1.4108E-06"
        rpy="0 0 0" />
    <mass
        value="0.10689" />
      <inertia
        ixx="3.2684e-05"
        ixy="-2.5662e-09"
        ixz="2.5662e-09"
        iyy="8.4132e-05"
        iyz="-2.1275e-13"
        izz="8.4583e-05" />
    </inertial>
    <visual>
      <origin
        xyz="0 0 0"
        rpy="0 0 0" />
      <geometry>
        <mesh
          filename="package://meshes/module9.STL" />
      </geometry>
      <material
        name="">
        <color
          rgba="0.79216 0.81961 0.93333 1" />
      </material>
    </visual>
    <collision>
      <origin
        xyz="0 0 0"
        rpy="0 0 0" />
      <geometry>
        <mesh
          filename="package://meshes/module9.STL" />
      </geometry>
    </collision>
  </link>
  <joint
    name="151_152"
    type="revolute">
    <origin
      xyz="0.0816 0 0"
      rpy="4.712389 0 0" />
    <parent
      link="151" />
    <child
      link="152" />
    <axis
      xyz="0 0 1" />
    <limit
      lower="-6.28"
      upper="6.28"
      effort="10"
      velocity="100" />
  </joint>
  <link
    name="153">
    <inertial>
      <origin
        xyz="0.051733 -0.042281 -1.3878E-17"
        rpy="0 0 0" />
    <mass
        value="0.12059" />
      <inertia
        ixx="0.00025425"
        ixy="4.8319E-05"
        ixz="0"
        iyy="5.0194E-05"
        iyz="-3.3141E-21"
        izz="0.00027482" />
    </inertial>
    <visual>
      <origin
        xyz="0 0 0"
        rpy="0 0 0" />
      <geometry>
        <mesh
          filename="package://meshes/leg.STL" />
      </geometry>
      <material
        name="">
        <color
          rgba="0.79216 0.81961 0.93333 1" />
      </material>
    </visual>
    <collision>
      <origin
        xyz="0 0 0"
        rpy="0 0 0" />
      <geometry>
        <mesh
          filename="package://meshes/leg.STL" />
      </geometry>
    </collision>
  </link>
  <joint
    name="152_153"
    type="revolute">
    <origin
      xyz="0.0816 0 0"
      rpy="4.712389 0 0" />
    <parent
      link="152" />
    <child
      link="153" />
    <axis
      xyz="0 0 1" />
    <limit
      lower="-6.28"
      upper="6.28"
      effort="10"
      velocity="100" />
  </joint>
  <link
   name="110">
   <inertial>
      <origin
        xyz="0 0 0.028508"
        rpy="0 0 0" />
      <mass
        value="0.076173" />
      <inertia
        ixx="3.054E-05"
        ixy="-0.000000"
        ixz="-0.000000"
        iyy="2.1077E-05"
        iyz="-0.000000"
        izz="2.1165E-05" />
    </inertial>
    <visual>
      <origin
        xyz="0 0 0"
        rpy="0 0 0" />
      <geometry>
        <mesh
          filename="package://meshes/1.STL" />
      </geometry>
      <material
        name="">
        <color
          rgba="1 1 1 1" />
      </material>
    </visual>
    <collision>
      <origin
        xyz="0 0 0"
        rpy="0 0 0" />
      <geometry>
        <mesh
          filename="package://meshes/1.STL" />
      </geometry>
    </collision>
  </link>
  <joint
    name="body_110"
    type="fixed">
    <origin
        xyz="0.083523 0.027138 -0.016769"
        rpy="1.759466 -0.000000 1.884956" />
    <parent
      link="base_link" />
    <child
      link="110" />
    <axis
      xyz="0 0 0" />
  </joint>
  <link
    name="111">
    <inertial>
      <origin
        xyz="0.060018 -1.4108E-06 1.4108E-06"
        rpy="0 0 0" />
    <mass
        value="0.10689" />
      <inertia
        ixx="3.2684e-05"
        ixy="-2.5662e-09"
        ixz="2.5662e-09"
        iyy="8.6498e-05"
        iyz="4.0975e-06"
        izz="8.2217e-05" />
    </inertial>
    <visual>
      <origin
        xyz="0 0 0"
        rpy="0 0 0" />
      <geometry>
        <mesh
          filename="package://meshes/module2.STL" />
      </geometry>
      <material
        name="">
        <color
          rgba="0.79216 0.81961 0.93333 1" />
      </material>
    </visual>
    <collision>
      <origin
        xyz="0 0 0"
        rpy="0 0 0" />
      <geometry>
        <mesh
          filename="package://meshes/module2.STL" />
      </geometry>
    </collision>
  </link>
  <joint
    name="110_111"
    type="revolute">
    <origin
      xyz="0 0 0.04"
      rpy="-1.558 -1.5708 -0.012835" />
    <parent
      link="110" />
    <child
      link="111" />
    <axis
      xyz="0 0 1" />
    <limit
      lower="-6.28"
      upper="6.28"
      effort="10"
      velocity="100" />
  </joint>
  <link
    name="112">
    <inertial>
      <origin
        xyz="0.060018 -1.4108E-06 1.4108E-06"
        rpy="0 0 0" />
    <mass
        value="0.10689" />
      <inertia
        ixx="3.2684e-05"
        ixy="-2.5662e-09"
        ixz="2.5662e-09"
        iyy="9.3595e-05"
        iyz="-2.1275e-13"
        izz="7.512e-05" />
    </inertial>
    <visual>
      <origin
        xyz="0 0 0"
        rpy="0 0 0" />
      <geometry>
        <mesh
          filename="package://meshes/module0.STL" />
      </geometry>
      <material
        name="">
        <color
          rgba="0.79216 0.81961 0.93333 1" />
      </material>
    </visual>
    <collision>
      <origin
        xyz="0 0 0"
        rpy="0 0 0" />
      <geometry>
        <mesh
          filename="package://meshes/module0.STL" />
      </geometry>
    </collision>
  </link>
  <joint
    name="111_112"
    type="revolute">
    <origin
      xyz="0.0816 0 0"
      rpy="1.047198 0 0" />
    <parent
      link="111" />
    <child
      link="112" />
    <axis
      xyz="0 0 1" />
    <limit
      lower="-6.28"
      upper="6.28"
      effort="10"
      velocity="100" />
  </joint>
  <link
    name="113">
    <inertial>
      <origin
        xyz="0.051733 -0.042281 -1.3878E-17"
        rpy="0 0 0" />
    <mass
        value="0.12059" />
      <inertia
        ixx="0.00025425"
        ixy="4.8319E-05"
        ixz="0"
        iyy="5.0194E-05"
        iyz="-3.3141E-21"
        izz="0.00027482" />
    </inertial>
    <visual>
      <origin
        xyz="0 0 0"
        rpy="0 0 0" />
      <geometry>
        <mesh
          filename="package://meshes/leg.STL" />
      </geometry>
      <material
        name="">
        <color
          rgba="0.79216 0.81961 0.93333 1" />
      </material>
    </visual>
    <collision>
      <origin
        xyz="0 0 0"
        rpy="0 0 0" />
      <geometry>
        <mesh
          filename="package://meshes/leg.STL" />
      </geometry>
    </collision>
  </link>
  <joint
    name="112_113"
    type="revolute">
    <origin
      xyz="0.0816 0 0"
      rpy="0.000000 0 0" />
    <parent
      link="112" />
    <child
      link="113" />
    <axis
      xyz="0 0 1" />
    <limit
      lower="-6.28"
      upper="6.28"
      effort="10"
      velocity="100" />
  </joint>
  <link
   name="130">
   <inertial>
      <origin
        xyz="0 0 0.028508"
        rpy="0 0 0" />
      <mass
        value="0.076173" />
      <inertia
        ixx="3.054E-05"
        ixy="-0.000000"
        ixz="-0.000000"
        iyy="2.1077E-05"
        iyz="0.000000"
        izz="2.1165E-05" />
    </inertial>
    <visual>
      <origin
        xyz="0 0 0"
        rpy="0 0 0" />
      <geometry>
        <mesh
          filename="package://meshes/1.STL" />
      </geometry>
      <material
        name="">
        <color
          rgba="1 1 1 1" />
      </material>
    </visual>
    <collision>
      <origin
        xyz="0 0 0"
        rpy="0 0 0" />
      <geometry>
        <mesh
          filename="package://meshes/1.STL" />
      </geometry>
    </collision>
  </link>
  <joint
    name="body_130"
    type="fixed">
    <origin
        xyz="-0.083523 0.027138 -0.016769"
        rpy="-1.759466 -0.000000 1.256637" />
    <parent
      link="base_link" />
    <child
      link="130" />
    <axis
      xyz="0 0 0" />
  </joint>
  <link
    name="131">
    <inertial>
      <origin
        xyz="0.060018 -1.4108E-06 1.4108E-06"
        rpy="0 0 0" />
    <mass
        value="0.10689" />
      <inertia
        ixx="3.2684e-05"
        ixy="-2.5662e-09"
        ixz="2.5662e-09"
        iyy="8.6498e-05"
        iyz="-4.0975e-06"
        izz="8.2217e-05" />
    </inertial>
    <visual>
      <origin
        xyz="0 0 0"
        rpy="0 0 0" />
      <geometry>
        <mesh
          filename="package://meshes/module10.STL" />
      </geometry>
      <material
        name="">
        <color
          rgba="0.79216 0.81961 0.93333 1" />
      </material>
    </visual>
    <collision>
      <origin
        xyz="0 0 0"
        rpy="0 0 0" />
      <geometry>
        <mesh
          filename="package://meshes/module10.STL" />
      </geometry>
    </collision>
  </link>
  <joint
    name="130_131"
    type="revolute">
    <origin
      xyz="0 0 0.04"
      rpy="-1.558 -1.5708 -0.012835" />
    <parent
      link="130" />
    <child
      link="131" />
    <axis
      xyz="0 0 1" />
    <limit
      lower="-6.28"
      upper="6.28"
      effort="10"
      velocity="100" />
  </joint>
  <link
    name="132">
    <inertial>
      <origin
        xyz="0.060018 -1.4108E-06 1.4108E-06"
        rpy="0 0 0" />
    <mass
        value="0.10689" />
      <inertia
        ixx="3.2684e-05"
        ixy="-2.5662e-09"
        ixz="2.5662e-09"
        iyy="9.3595e-05"
        iyz="-2.1275e-13"
        izz="7.512e-05" />
    </inertial>
    <visual>
      <origin
        xyz="0 0 0"
        rpy="0 0 0" />
      <geometry>
        <mesh
          filename="package://meshes/module0.STL" />
      </geometry>
      <material
        name="">
        <color
          rgba="0.79216 0.81961 0.93333 1" />
      </material>
    </visual>
    <collision>
      <origin
        xyz="0 0 0"
        rpy="0 0 0" />
      <geometry>
        <mesh
          filename="package://meshes/module0.STL" />
      </geometry>
    </collision>
  </link>
  <joint
    name="131_132"
    type="revolute">
    <origin
      xyz="0.0816 0 0"
      rpy="5.235988 0 0" />
    <parent
      link="131" />
    <child
      link="132" />
    <axis
      xyz="0 0 1" />
    <limit
      lower="-6.28"
      upper="6.28"
      effort="10"
      velocity="100" />
  </joint>
  <link
    name="133">
    <inertial>
      <origin
        xyz="0.051733 -0.042281 -1.3878E-17"
        rpy="0 0 0" />
    <mass
        value="0.12059" />
      <inertia
        ixx="0.00025425"
        ixy="4.8319E-05"
        ixz="0"
        iyy="5.0194E-05"
        iyz="-3.3141E-21"
        izz="0.00027482" />
    </inertial>
    <visual>
      <origin
        xyz="0 0 0"
        rpy="0 0 0" />
      <geometry>
        <mesh
          filename="package://meshes/leg.STL" />
      </geometry>
      <material
        name="">
        <color
          rgba="0.79216 0.81961 0.93333 1" />
      </material>
    </visual>
    <collision>
      <origin
        xyz="0 0 0"
        rpy="0 0 0" />
      <geometry>
        <mesh
          filename="package://meshes/leg.STL" />
      </geometry>
    </collision>
  </link>
  <joint
    name="132_133"
    type="revolute">
    <origin
      xyz="0.0816 0 0"
      rpy="0.000000 0 0" />
    <parent
      link="132" />
    <child
      link="133" />
    <axis
      xyz="0 0 1" />
    <limit
      lower="-6.28"
      upper="6.28"
      effort="10"
      velocity="100" />
  </joint>
  <link
   name="190">
   <inertial>
      <origin
        xyz="0 0 0.028508"
        rpy="0 0 0" />
      <mass
        value="0.076173" />
      <inertia
        ixx="3.054E-05"
        ixy="-0.000000"
        ixz="-0.000000"
        iyy="2.1077E-05"
        iyz="0.000000"
        izz="2.1165E-05" />
    </inertial>
    <visual>
      <origin
        xyz="0 0 0"
        rpy="0 0 0" />
      <geometry>
        <mesh
          filename="package://meshes/1.STL" />
      </geometry>
      <material
        name="">
        <color
          rgba="1 1 1 1" />
      </material>
    </visual>
    <collision>
      <origin
        xyz="0 0 0"
        rpy="0 0 0" />
      <geometry>
        <mesh
          filename="package://meshes/1.STL" />
      </geometry>
    </collision>
  </link>
  <joint
    name="body_190"
    type="fixed">
    <origin
        xyz="-0.031905 -0.043913 -0.071046"
        rpy="-2.489189 -0.000000 2.513274" />
    <parent
      link="base_link" />
    <child
      link="190" />
    <axis
      xyz="0 0 0" />
  </joint>
  <link
    name="191">
    <inertial>
      <origin
        xyz="0.060018 -1.4108E-06 1.4108E-06"
        rpy="0 0 0" />
    <mass
        value="0.10689" />
      <inertia
        ixx="3.2684e-05"
        ixy="-2.5662e-09"
        ixz="2.5662e-09"
        iyy="8.4132e-05"
        iyz="-2.1275e-13"
        izz="8.4583e-05" />
    </inertial>
    <visual>
      <origin
        xyz="0 0 0"
        rpy="0 0 0" />
      <geometry>
        <mesh
          filename="package://meshes/module3.STL" />
      </geometry>
      <material
        name="">
        <color
          rgba="0.79216 0.81961 0.93333 1" />
      </material>
    </visual>
    <collision>
      <origin
        xyz="0 0 0"
        rpy="0 0 0" />
      <geometry>
        <mesh
          filename="package://meshes/module3.STL" />
      </geometry>
    </collision>
  </link>
  <joint
    name="190_191"
    type="revolute">
    <origin
      xyz="0 0 0.04"
      rpy="-1.558 -1.5708 -0.012835" />
    <parent
      link="190" />
    <child
      link="191" />
    <axis
      xyz="0 0 1" />
    <limit
      lower="-6.28"
      upper="6.28"
      effort="10"
      velocity="100" />
  </joint>
  <link
    name="192">
    <inertial>
      <origin
        xyz="0.060018 -1.4108E-06 1.4108E-06"
        rpy="0 0 0" />
    <mass
        value="0.10689" />
      <inertia
        ixx="3.2684e-05"
        ixy="-2.5662e-09"
        ixz="2.5662e-09"
        iyy="8.4132e-05"
        iyz="-2.1275e-13"
        izz="8.4583e-05" />
    </inertial>
    <visual>
      <origin
        xyz="0 0 0"
        rpy="0 0 0" />
      <geometry>
        <mesh
          filename="package://meshes/module3.STL" />
      </geometry>
      <material
        name="">
        <color
          rgba="0.79216 0.81961 0.93333 1" />
      </material>
    </visual>
    <collision>
      <origin
        xyz="0 0 0"
        rpy="0 0 0" />
      <geometry>
        <mesh
          filename="package://meshes/module3.STL" />
      </geometry>
    </collision>
  </link>
  <joint
    name="191_192"
    type="revolute">
    <origin
      xyz="0.0816 0 0"
      rpy="1.570796 0 0" />
    <parent
      link="191" />
    <child
      link="192" />
    <axis
      xyz="0 0 1" />
    <limit
      lower="-6.28"
      upper="6.28"
      effort="10"
      velocity="100" />
  </joint>
  <link
    name="193">
    <inertial>
      <origin
        xyz="0.051733 -0.042281 -1.3878E-17"
        rpy="0 0 0" />
    <mass
        value="0.12059" />
      <inertia
        ixx="0.00025425"
        ixy="4.8319E-05"
        ixz="0"
        iyy="5.0194E-05"
        iyz="-3.3141E-21"
        izz="0.00027482" />
    </inertial>
    <visual>
      <origin
        xyz="0 0 0"
        rpy="0 0 0" />
      <geometry>
        <mesh
          filename="package://meshes/leg.STL" />
      </geometry>
      <material
        name="">
        <color
          rgba="0.79216 0.81961 0.93333 1" />
      </material>
    </visual>
    <collision>
      <origin
        xyz="0 0 0"
        rpy="0 0 0" />
      <geometry>
        <mesh
          filename="package://meshes/leg.STL" />
      </geometry>
    </collision>
  </link>
  <joint
    name="192_193"
    type="revolute">
    <origin
      xyz="0.0816 0 0"
      rpy="1.570796 0 0" />
    <parent
      link="192" />
    <child
      link="193" />
    <axis
      xyz="0 0 1" />
    <limit
      lower="-6.28"
      upper="6.28"
      effort="10"
      velocity="100" />
  </joint>
  <link
    name = "ball_1">
    <inertial>
    <origin
        xyz="0 0 0"
        rpy="0 0 0" />
    <mass
        value="0" />
      <inertia
        ixx="0"
        ixy="0"
        ixz="0"
        iyy="0"
        iyz="0"
        izz="0" />
    </inertial>    <visual>
      <origin
        xyz="0 0 0"
        rpy="0 0 0" />
     <geometry>
        <sphere radius = "0.01"/>
      </geometry>
      <material
        name="green">
        <color
          rgba="0.22 1 0.4 1" />
      </material>
    </visual>
  </link>
  <joint
  name="153_ball1"
  type="fixed">
    <origin
      xyz="0.0612 -0.13431 0"
      rpy="0 0 0" />
    <parent
      link="153" />
    <child
      link="ball_1" />
    <axis
      xyz="0 0 0" />
  </joint>
  <link
    name = "ball_2">
    <inertial>
    <origin
        xyz="0 0 0"
        rpy="0 0 0" />
    <mass
        value="0" />
      <inertia
        ixx="0"
        ixy="0"
        ixz="0"
        iyy="0"
        iyz="0"
        izz="0" />
    </inertial>    <visual>
      <origin
        xyz="0 0 0"
        rpy="0 0 0" />
      <geometry>
        <sphere radius = "0.01"/>
      </geometry>
      <material
        name="blue">
        <color
          rgba="0.16 0.52 0.8 1" />
      </material>
    </visual>
  </link>
  <joint
  name="113_ball2"
  type="fixed">
    <origin
      xyz="0.0612 -0.13431 0"
      rpy="0 0 0" />
    <parent
      link="113" />
    <child
      link="ball_2" />
    <axis
      xyz="0 0 0" />
  </joint>
  <link
    name = "ball_3">
    <inertial>
    <origin
        xyz="0 0 0"
        rpy="0 0 0" />
    <mass
        value="0" />
      <inertia
        ixx="0"
        ixy="0"
        ixz="0"
        iyy="0"
        iyz="0"
        izz="0" />
    </inertial>    <visual>
      <origin
        xyz="0 0 0"
        rpy="0 0 0" />
     <geometry>
        <sphere radius = "0.01"/>
      </geometry>
      <material
        name="blue">
        <color
          rgba="0.16 0.52 0.8 1" />
      </material>
    </visual>
  </link>
  <joint
  name="133_ball3"
  type="fixed">
    <origin
      xyz="0.0612 -0.13431 0"
      rpy="0 0 0" />
    <parent
      link="133" />
    <child
      link="ball_3" />
    <axis
      xyz="0 0 0" />
  </joint>
  <link
    name = "ball_4">
    <inertial>
    <origin
        xyz="0 0 0"
        rpy="0 0 0" />
    <mass
        value="0" />
      <inertia
        ixx="0"
        ixy="0"
        ixz="0"
        iyy="0"
        iyz="0"
        izz="0" />
    </inertial>    <visual>
      <origin
        xyz="0 0 0"
        rpy="0 0 0" />
      <geometry>
        <sphere radius = "0.01"/>
      </geometry>
      <material
        name="yellow">
        <color
          rgba="1 1 0 1" />
      </material>
    </visual>
  </link>
  <joint
  name="193_ball4"
  type="fixed">
    <origin
      xyz="0.0612 -0.13431 0"
      rpy="0 0 0" />
    <parent
      link="193" />
    <child
      link="ball_4" />
    <axis
      xyz="0 0 0" />
  </joint>
</robot>