<?xml version="1.0" encoding="utf-8"?>
<robot
  name="mod_test">
  <link
    name="base_link">
    <inertial>
      <origin
        xyz="-1.5226495220944E-06 1.5812928362389E-07 -5.05247252856584E-07"
        rpy="0 0 0" />
      <mass
        value="0.422806992949252" />
      <inertia
        ixx="0.00237499139253511"
        ixy="1.5717831530364E-08"
        ixz="1.49286265366169E-08"
        iyy="0.00237502154661776"
        iyz="-2.02154172619351E-08"
        izz="0.00237502595466009" />
    </inertial>
    <visual>
      <origin
        xyz="0 0 0"
        rpy="0 0 0" />
      <geometry>
        <mesh
          filename="package://meshes/base_link.STL" />
      </geometry>
      <material
        name="">
        <color
          rgba="0.498039215686275 0.498039215686275 0.498039215686275 1" />
      </material>
    </visual>
    <collision>
      <origin
        xyz="0 0 0"
        rpy="0 0 0" />
      <geometry>
        <mesh
          filename="package://meshes/base_link.STL" />
      </geometry>
    </collision>
  </link>
  <link
   name="160">
   <inertial>
      <origin
        xyz="0 0 0.028508"
        rpy="0 0 0" />
      <mass
        value="0.076173" />
      <inertia
        ixx="3.054E-05"
        ixy="-0.000000"
        ixz="-0.000000"
        iyy="2.1077E-05"
        iyz="-0.000000"
        izz="2.1165E-05" />
    </inertial>
    <visual>
      <origin
        xyz="0 0 0"
        rpy="0 0 0" />
      <geometry>
        <mesh
          filename="package://meshes/1.STL" />
      </geometry>
      <material
        name="">
        <color
          rgba="1 1 1 1" />
      </material>
    </visual>
    <collision>
      <origin
        xyz="0 0 0"
        rpy="0 0 0" />
      <geometry>
        <mesh
          filename="package://meshes/1.STL" />
      </geometry>
    </collision>
  </link>
  <joint
    name="body_160"
    type="fixed">
    <origin
        xyz="0.051623 0.016773 -0.071046"
        rpy="2.489189 -0.000000 1.884956" />
    <parent
      link="base_link" />
    <child
      link="160" />
    <axis
      xyz="0 0 0" />
  </joint>
  <link
    name="161">
    <inertial>
      <origin
        xyz="0.060018 -1.4108E-06 1.4108E-06"
        rpy="0 0 0" />
    <mass
        value="0.10689" />
      <inertia
        ixx="3.2684e-05"
        ixy="-2.5662e-09"
        ixz="2.5662e-09"
        iyy="8.6498e-05"
        iyz="-4.0975e-06"
        izz="8.2217e-05" />
    </inertial>
    <visual>
      <origin
        xyz="0 0 0"
        rpy="0 0 0" />
      <geometry>
        <mesh
          filename="package://meshes/module10.STL" />
      </geometry>
      <material
        name="">
        <color
          rgba="0.79216 0.81961 0.93333 1" />
      </material>
    </visual>
    <collision>
      <origin
        xyz="0 0 0"
        rpy="0 0 0" />
      <geometry>
        <mesh
          filename="package://meshes/module10.STL" />
      </geometry>
    </collision>
  </link>
  <joint
    name="160_161"
    type="revolute">
    <origin
      xyz="0 0 0.04"
      rpy="-1.558 -1.5708 -0.012835" />
    <parent
      link="160" />
    <child
      link="161" />
    <axis
      xyz="0 0 1" />
    <limit
      lower="-6.28"
      upper="6.28"
      effort="10"
      velocity="100" />
  </joint>
  <link
    name="162">
    <inertial>
      <origin
        xyz="0.060018 -1.4108E-06 1.4108E-06"
        rpy="0 0 0" />
    <mass
        value="0.10689" />
      <inertia
        ixx="3.2684e-05"
        ixy="-2.5662e-09"
        ixz="2.5662e-09"
        iyy="9.3595e-05"
        iyz="-2.1275e-13"
        izz="7.512e-05" />
    </inertial>
    <visual>
      <origin
        xyz="0 0 0"
        rpy="0 0 0" />
      <geometry>
        <mesh
          filename="package://meshes/module6.STL" />
      </geometry>
      <material
        name="">
        <color
          rgba="0.79216 0.81961 0.93333 1" />
      </material>
    </visual>
    <collision>
      <origin
        xyz="0 0 0"
        rpy="0 0 0" />
      <geometry>
        <mesh
          filename="package://meshes/module6.STL" />
      </geometry>
    </collision>
  </link>
  <joint
    name="161_162"
    type="revolute">
    <origin
      xyz="0.0816 0 0"
      rpy="5.235988 0 0" />
    <parent
      link="161" />
    <child
      link="162" />
    <axis
      xyz="0 0 1" />
    <limit
      lower="-6.28"
      upper="6.28"
      effort="10"
      velocity="100" />
  </joint>
  <link
    name="163">
    <inertial>
      <origin
        xyz="0.051733 -0.042281 -1.3878E-17"
        rpy="0 0 0" />
    <mass
        value="0.12059" />
      <inertia
        ixx="0.00025425"
        ixy="4.8319E-05"
        ixz="0"
        iyy="5.0194E-05"
        iyz="-3.3141E-21"
        izz="0.00027482" />
    </inertial>
    <visual>
      <origin
        xyz="0 0 0"
        rpy="0 0 0" />
      <geometry>
        <mesh
          filename="package://meshes/leg.STL" />
      </geometry>
      <material
        name="">
        <color
          rgba="0.79216 0.81961 0.93333 1" />
      </material>
    </visual>
    <collision>
      <origin
        xyz="0 0 0"
        rpy="0 0 0" />
      <geometry>
        <mesh
          filename="package://meshes/leg.STL" />
      </geometry>
    </collision>
  </link>
  <joint
    name="162_163"
    type="revolute">
    <origin
      xyz="0.0816 0 0"
      rpy="3.141593 0 0" />
    <parent
      link="162" />
    <child
      link="163" />
    <axis
      xyz="0 0 1" />
    <limit
      lower="-6.28"
      upper="6.28"
      effort="10"
      velocity="100" />
  </joint>
  <link
   name="150">
   <inertial>
      <origin
        xyz="0 0 0.028508"
        rpy="0 0 0" />
      <mass
        value="0.076173" />
      <inertia
        ixx="3.054E-05"
        ixy="0.000000"
        ixz="-0.000000"
        iyy="2.1077E-05"
        iyz="-0.000000"
        izz="2.1165E-05" />
    </inertial>
    <visual>
      <origin
        xyz="0 0 0"
        rpy="0 0 0" />
      <geometry>
        <mesh
          filename="package://meshes/1.STL" />
      </geometry>
      <material
        name="">
        <color
          rgba="1 1 1 1" />
      </material>
    </visual>
    <collision>
      <origin
        xyz="0 0 0"
        rpy="0 0 0" />
      <geometry>
        <mesh
          filename="package://meshes/1.STL" />
      </geometry>
    </collision>
  </link>
  <joint
    name="body_150"
    type="fixed">
    <origin
        xyz="0.031905 -0.043913 -0.071046"
        rpy="2.776697 -0.553612 -0.314143" />
    <parent
      link="base_link" />
    <child
      link="150" />
    <axis
      xyz="0 0 0" />
  </joint>
  <link
    name="151">
    <inertial>
      <origin
        xyz="0.060018 -1.4108E-06 1.4108E-06"
        rpy="0 0 0" />
    <mass
        value="0.10689" />
      <inertia
        ixx="3.2684e-05"
        ixy="-2.5662e-09"
        ixz="2.5662e-09"
        iyy="9.3595e-05"
        iyz="-2.1275e-13"
        izz="7.512e-05" />
    </inertial>
    <visual>
      <origin
        xyz="0 0 0"
        rpy="0 0 0" />
      <geometry>
        <mesh
          filename="package://meshes/module6.STL" />
      </geometry>
      <material
        name="">
        <color
          rgba="0.79216 0.81961 0.93333 1" />
      </material>
    </visual>
    <collision>
      <origin
        xyz="0 0 0"
        rpy="0 0 0" />
      <geometry>
        <mesh
          filename="package://meshes/module6.STL" />
      </geometry>
    </collision>
  </link>
  <joint
    name="150_151"
    type="revolute">
    <origin
      xyz="0 0 0.04"
      rpy="-1.558 -1.5708 -0.012835" />
    <parent
      link="150" />
    <child
      link="151" />
    <axis
      xyz="0 0 1" />
    <limit
      lower="-6.28"
      upper="6.28"
      effort="10"
      velocity="100" />
  </joint>
  <link
    name="152">
    <inertial>
      <origin
        xyz="0.060018 -1.4108E-06 1.4108E-06"
        rpy="0 0 0" />
    <mass
        value="0.10689" />
      <inertia
        ixx="3.2684e-05"
        ixy="-2.5662e-09"
        ixz="2.5662e-09"
        iyy="8.4132e-05"
        iyz="-2.1275e-13"
        izz="8.4583e-05" />
    </inertial>
    <visual>
      <origin
        xyz="0 0 0"
        rpy="0 0 0" />
      <geometry>
        <mesh
          filename="package://meshes/module9.STL" />
      </geometry>
      <material
        name="">
        <color
          rgba="0.79216 0.81961 0.93333 1" />
      </material>
    </visual>
    <collision>
      <origin
        xyz="0 0 0"
        rpy="0 0 0" />
      <geometry>
        <mesh
          filename="package://meshes/module9.STL" />
      </geometry>
    </collision>
  </link>
  <joint
    name="151_152"
    type="revolute">
    <origin
      xyz="0.0816 0 0"
      rpy="3.141593 0 0" />
    <parent
      link="151" />
    <child
      link="152" />
    <axis
      xyz="0 0 1" />
    <limit
      lower="-6.28"
      upper="6.28"
      effort="10"
      velocity="100" />
  </joint>
  <link
    name="153">
    <inertial>
      <origin
        xyz="0.051733 -0.042281 -1.3878E-17"
        rpy="0 0 0" />
    <mass
        value="0.12059" />
      <inertia
        ixx="0.00025425"
        ixy="4.8319E-05"
        ixz="0"
        iyy="5.0194E-05"
        iyz="-3.3141E-21"
        izz="0.00027482" />
    </inertial>
    <visual>
      <origin
        xyz="0 0 0"
        rpy="0 0 0" />
      <geometry>
        <mesh
          filename="package://meshes/leg.STL" />
      </geometry>
      <material
        name="">
        <color
          rgba="0.79216 0.81961 0.93333 1" />
      </material>
    </visual>
    <collision>
      <origin
        xyz="0 0 0"
        rpy="0 0 0" />
      <geometry>
        <mesh
          filename="package://meshes/leg.STL" />
      </geometry>
    </collision>
  </link>
  <joint
    name="152_153"
    type="revolute">
    <origin
      xyz="0.0816 0 0"
      rpy="4.712389 0 0" />
    <parent
      link="152" />
    <child
      link="153" />
    <axis
      xyz="0 0 1" />
    <limit
      lower="-6.28"
      upper="6.28"
      effort="10"
      velocity="100" />
  </joint>
  <link
   name="190">
   <inertial>
      <origin
        xyz="0 0 0.028508"
        rpy="0 0 0" />
      <mass
        value="0.076173" />
      <inertia
        ixx="3.054E-05"
        ixy="0.000000"
        ixz="0.000000"
        iyy="2.1077E-05"
        iyz="0.000021"
        izz="2.1165E-05" />
    </inertial>
    <visual>
      <origin
        xyz="0 0 0"
        rpy="0 0 0" />
      <geometry>
        <mesh
          filename="package://meshes/1.STL" />
      </geometry>
      <material
        name="">
        <color
          rgba="1 1 1 1" />
      </material>
    </visual>
    <collision>
      <origin
        xyz="0 0 0"
        rpy="0 0 0" />
      <geometry>
        <mesh
          filename="package://meshes/1.STL" />
      </geometry>
    </collision>
  </link>
  <joint
    name="body_190"
    type="fixed">
    <origin
        xyz="-0.031905 -0.043913 -0.071046"
        rpy="-2.776697 -0.553612 -2.827450" />
    <parent
      link="base_link" />
    <child
      link="190" />
    <axis
      xyz="0 0 0" />
  </joint>
  <link
    name="191">
    <inertial>
      <origin
        xyz="0.060018 -1.4108E-06 1.4108E-06"
        rpy="0 0 0" />
    <mass
        value="0.10689" />
      <inertia
        ixx="3.2684e-05"
        ixy="-2.5662e-09"
        ixz="2.5662e-09"
        iyy="9.3595e-05"
        iyz="-2.1275e-13"
        izz="7.512e-05" />
    </inertial>
    <visual>
      <origin
        xyz="0 0 0"
        rpy="0 0 0" />
      <geometry>
        <mesh
          filename="package://meshes/module6.STL" />
      </geometry>
      <material
        name="">
        <color
          rgba="0.79216 0.81961 0.93333 1" />
      </material>
    </visual>
    <collision>
      <origin
        xyz="0 0 0"
        rpy="0 0 0" />
      <geometry>
        <mesh
          filename="package://meshes/module6.STL" />
      </geometry>
    </collision>
  </link>
  <joint
    name="190_191"
    type="revolute">
    <origin
      xyz="0 0 0.04"
      rpy="-1.558 -1.5708 -0.012835" />
    <parent
      link="190" />
    <child
      link="191" />
    <axis
      xyz="0 0 1" />
    <limit
      lower="-6.28"
      upper="6.28"
      effort="10"
      velocity="100" />
  </joint>
  <link
    name="192">
    <inertial>
      <origin
        xyz="0.060018 -1.4108E-06 1.4108E-06"
        rpy="0 0 0" />
    <mass
        value="0.10689" />
      <inertia
        ixx="3.2684e-05"
        ixy="-2.5662e-09"
        ixz="2.5662e-09"
        iyy="8.4132e-05"
        iyz="-2.1275e-13"
        izz="8.4583e-05" />
    </inertial>
    <visual>
      <origin
        xyz="0 0 0"
        rpy="0 0 0" />
      <geometry>
        <mesh
          filename="package://meshes/module3.STL" />
      </geometry>
      <material
        name="">
        <color
          rgba="0.79216 0.81961 0.93333 1" />
      </material>
    </visual>
    <collision>
      <origin
        xyz="0 0 0"
        rpy="0 0 0" />
      <geometry>
        <mesh
          filename="package://meshes/module3.STL" />
      </geometry>
    </collision>
  </link>
  <joint
    name="191_192"
    type="revolute">
    <origin
      xyz="0.0816 0 0"
      rpy="3.141593 0 0" />
    <parent
      link="191" />
    <child
      link="192" />
    <axis
      xyz="0 0 1" />
    <limit
      lower="-6.28"
      upper="6.28"
      effort="10"
      velocity="100" />
  </joint>
  <link
    name="193">
    <inertial>
      <origin
        xyz="0.051733 -0.042281 -1.3878E-17"
        rpy="0 0 0" />
    <mass
        value="0.12059" />
      <inertia
        ixx="0.00025425"
        ixy="4.8319E-05"
        ixz="0"
        iyy="5.0194E-05"
        iyz="-3.3141E-21"
        izz="0.00027482" />
    </inertial>
    <visual>
      <origin
        xyz="0 0 0"
        rpy="0 0 0" />
      <geometry>
        <mesh
          filename="package://meshes/leg.STL" />
      </geometry>
      <material
        name="">
        <color
          rgba="0.79216 0.81961 0.93333 1" />
      </material>
    </visual>
    <collision>
      <origin
        xyz="0 0 0"
        rpy="0 0 0" />
      <geometry>
        <mesh
          filename="package://meshes/leg.STL" />
      </geometry>
    </collision>
  </link>
  <joint
    name="192_193"
    type="revolute">
    <origin
      xyz="0.0816 0 0"
      rpy="1.570796 0 0" />
    <parent
      link="192" />
    <child
      link="193" />
    <axis
      xyz="0 0 1" />
    <limit
      lower="-6.28"
      upper="6.28"
      effort="10"
      velocity="100" />
  </joint>
  <link
   name="180">
   <inertial>
      <origin
        xyz="0 0 0.028508"
        rpy="0 0 0" />
      <mass
        value="0.076173" />
      <inertia
        ixx="3.054E-05"
        ixy="-0.000000"
        ixz="-0.000000"
        iyy="2.1077E-05"
        iyz="0.000000"
        izz="2.1165E-05" />
    </inertial>
    <visual>
      <origin
        xyz="0 0 0"
        rpy="0 0 0" />
      <geometry>
        <mesh
          filename="package://meshes/1.STL" />
      </geometry>
      <material
        name="">
        <color
          rgba="1 1 1 1" />
      </material>
    </visual>
    <collision>
      <origin
        xyz="0 0 0"
        rpy="0 0 0" />
      <geometry>
        <mesh
          filename="package://meshes/1.STL" />
      </geometry>
    </collision>
  </link>
  <joint
    name="body_180"
    type="fixed">
    <origin
        xyz="-0.051623 0.016773 -0.071046"
        rpy="-2.489189 -0.000000 1.256637" />
    <parent
      link="base_link" />
    <child
      link="180" />
    <axis
      xyz="0 0 0" />
  </joint>
  <link
    name="181">
    <inertial>
      <origin
        xyz="0.060018 -1.4108E-06 1.4108E-06"
        rpy="0 0 0" />
    <mass
        value="0.10689" />
      <inertia
        ixx="3.2684e-05"
        ixy="-2.5662e-09"
        ixz="2.5662e-09"
        iyy="8.6498e-05"
        iyz="4.0975e-06"
        izz="8.2217e-05" />
    </inertial>
    <visual>
      <origin
        xyz="0 0 0"
        rpy="0 0 0" />
      <geometry>
        <mesh
          filename="package://meshes/module2.STL" />
      </geometry>
      <material
        name="">
        <color
          rgba="0.79216 0.81961 0.93333 1" />
      </material>
    </visual>
    <collision>
      <origin
        xyz="0 0 0"
        rpy="0 0 0" />
      <geometry>
        <mesh
          filename="package://meshes/module2.STL" />
      </geometry>
    </collision>
  </link>
  <joint
    name="180_181"
    type="revolute">
    <origin
      xyz="0 0 0.04"
      rpy="-1.558 -1.5708 -0.012835" />
    <parent
      link="180" />
    <child
      link="181" />
    <axis
      xyz="0 0 1" />
    <limit
      lower="-6.28"
      upper="6.28"
      effort="10"
      velocity="100" />
  </joint>
  <link
    name="182">
    <inertial>
      <origin
        xyz="0.060018 -1.4108E-06 1.4108E-06"
        rpy="0 0 0" />
    <mass
        value="0.10689" />
      <inertia
        ixx="3.2684e-05"
        ixy="-2.5662e-09"
        ixz="2.5662e-09"
        iyy="9.3595e-05"
        iyz="-2.1275e-13"
        izz="7.512e-05" />
    </inertial>
    <visual>
      <origin
        xyz="0 0 0"
        rpy="0 0 0" />
      <geometry>
        <mesh
          filename="package://meshes/module6.STL" />
      </geometry>
      <material
        name="">
        <color
          rgba="0.79216 0.81961 0.93333 1" />
      </material>
    </visual>
    <collision>
      <origin
        xyz="0 0 0"
        rpy="0 0 0" />
      <geometry>
        <mesh
          filename="package://meshes/module6.STL" />
      </geometry>
    </collision>
  </link>
  <joint
    name="181_182"
    type="revolute">
    <origin
      xyz="0.0816 0 0"
      rpy="1.047198 0 0" />
    <parent
      link="181" />
    <child
      link="182" />
    <axis
      xyz="0 0 1" />
    <limit
      lower="-6.28"
      upper="6.28"
      effort="10"
      velocity="100" />
  </joint>
  <link
    name="183">
    <inertial>
      <origin
        xyz="0.051733 -0.042281 -1.3878E-17"
        rpy="0 0 0" />
    <mass
        value="0.12059" />
      <inertia
        ixx="0.00025425"
        ixy="4.8319E-05"
        ixz="0"
        iyy="5.0194E-05"
        iyz="-3.3141E-21"
        izz="0.00027482" />
    </inertial>
    <visual>
      <origin
        xyz="0 0 0"
        rpy="0 0 0" />
      <geometry>
        <mesh
          filename="package://meshes/leg.STL" />
      </geometry>
      <material
        name="">
        <color
          rgba="0.79216 0.81961 0.93333 1" />
      </material>
    </visual>
    <collision>
      <origin
        xyz="0 0 0"
        rpy="0 0 0" />
      <geometry>
        <mesh
          filename="package://meshes/leg.STL" />
      </geometry>
    </collision>
  </link>
  <joint
    name="182_183"
    type="revolute">
    <origin
      xyz="0.0816 0 0"
      rpy="3.141593 0 0" />
    <parent
      link="182" />
    <child
      link="183" />
    <axis
      xyz="0 0 1" />
    <limit
      lower="-6.28"
      upper="6.28"
      effort="10"
      velocity="100" />
  </joint>
  <link
    name = "ball_1">
    <inertial>
    <origin
        xyz="0 0 0"
        rpy="0 0 0" />
    <mass
        value="0" />
      <inertia
        ixx="0"
        ixy="0"
        ixz="0"
        iyy="0"
        iyz="0"
        izz="0" />
    </inertial>    <visual>
      <origin
        xyz="0 0 0"
        rpy="0 0 0" />
     <geometry>
        <sphere radius = "0.01"/>
      </geometry>
      <material
        name="green">
        <color
          rgba="0.22 1 0.4 1" />
      </material>
    </visual>
  </link>
  <joint
  name="163_ball1"
  type="fixed">
    <origin
      xyz="0.0612 -0.13431 0"
      rpy="0 0 0" />
    <parent
      link="163" />
    <child
      link="ball_1" />
    <axis
      xyz="0 0 0" />
  </joint>
  <link
    name = "ball_2">
    <inertial>
    <origin
        xyz="0 0 0"
        rpy="0 0 0" />
    <mass
        value="0" />
      <inertia
        ixx="0"
        ixy="0"
        ixz="0"
        iyy="0"
        iyz="0"
        izz="0" />
    </inertial>    <visual>
      <origin
        xyz="0 0 0"
        rpy="0 0 0" />
      <geometry>
        <sphere radius = "0.01"/>
      </geometry>
      <material
        name="blue">
        <color
          rgba="0.16 0.52 0.8 1" />
      </material>
    </visual>
  </link>
  <joint
  name="153_ball2"
  type="fixed">
    <origin
      xyz="0.0612 -0.13431 0"
      rpy="0 0 0" />
    <parent
      link="153" />
    <child
      link="ball_2" />
    <axis
      xyz="0 0 0" />
  </joint>
  <link
    name = "ball_3">
    <inertial>
    <origin
        xyz="0 0 0"
        rpy="0 0 0" />
    <mass
        value="0" />
      <inertia
        ixx="0"
        ixy="0"
        ixz="0"
        iyy="0"
        iyz="0"
        izz="0" />
    </inertial>    <visual>
      <origin
        xyz="0 0 0"
        rpy="0 0 0" />
     <geometry>
        <sphere radius = "0.01"/>
      </geometry>
      <material
        name="blue">
        <color
          rgba="0.16 0.52 0.8 1" />
      </material>
    </visual>
  </link>
  <joint
  name="193_ball3"
  type="fixed">
    <origin
      xyz="0.0612 -0.13431 0"
      rpy="0 0 0" />
    <parent
      link="193" />
    <child
      link="ball_3" />
    <axis
      xyz="0 0 0" />
  </joint>
  <link
    name = "ball_4">
    <inertial>
    <origin
        xyz="0 0 0"
        rpy="0 0 0" />
    <mass
        value="0" />
      <inertia
        ixx="0"
        ixy="0"
        ixz="0"
        iyy="0"
        iyz="0"
        izz="0" />
    </inertial>    <visual>
      <origin
        xyz="0 0 0"
        rpy="0 0 0" />
      <geometry>
        <sphere radius = "0.01"/>
      </geometry>
      <material
        name="yellow">
        <color
          rgba="1 1 0 1" />
      </material>
    </visual>
  </link>
  <joint
  name="183_ball4"
  type="fixed">
    <origin
      xyz="0.0612 -0.13431 0"
      rpy="0 0 0" />
    <parent
      link="183" />
    <child
      link="ball_4" />
    <axis
      xyz="0 0 0" />
  </joint>
</robot>